Traceback (most recent call last):
  File "untuned.py", line 63, in <module>
    eval(cmd())
  File "<string>", line 1, in <module>
  File "untuned.py", line 25, in _test
    df=pd.read_csv("../data/"+res+".csv")
  File "/tmp/pip-build-CHwPXh/pandas/pandas/io/parsers.py", line 655, in parser_f
  File "/tmp/pip-build-CHwPXh/pandas/pandas/io/parsers.py", line 405, in _read
  File "/tmp/pip-build-CHwPXh/pandas/pandas/io/parsers.py", line 764, in __init__
  File "/tmp/pip-build-CHwPXh/pandas/pandas/io/parsers.py", line 985, in _make_engine
  File "/tmp/pip-build-CHwPXh/pandas/pandas/io/parsers.py", line 1605, in __init__
  File "pandas/_libs/parsers.pyx", line 394, in pandas._libs.parsers.TextReader.__cinit__ (pandas/_libs/parsers.c:4209)
  File "pandas/_libs/parsers.pyx", line 710, in pandas._libs.parsers.TextReader._setup_parser_source (pandas/_libs/parsers.c:8873)
IOError: File ../data/datatset1.csv does not exist
